Workbook

Sheet Implementation
A1: ID | B1: Name | C1: Programming language
C2: C | D2: Python
A3: T1 | B3: Bit fields | C3: x | D3: Does not have bit fields.
A4: T2 | B4: Bit sets | C4: x | D4: Does not have built-in support for bit sets.
A5: T3 | B5: Boolean return | C5: x | D5: Does not support returning multiple boolean values as a single unsigned int.
A6: T4 | B6: Cascaded function calls | C6: x | D6: x
A7: T5 | B7: Row-major accessing | C7: x | D7: x
A8: T6 | B8: Constructor initialization lists | C8: x | D8: Does not support constructor initialization lists.
A9: T7 | B9: Common subexpression elimination | C9: x | D9: x
A10: T8 | B10: Mapping structures | C10: x | D10: x
A11: T9 | B11: Dead code elimination | C11: x | D11: x
A12: T10 | B12: Exception handling | C12: x | D12: x
A13: T11 | B13: Global variables within loops | C13: x | D13: x
A14: T12 | B14: Function inlining | C14: x | D14: x
... A50: T51 | B50: Coarsening Recursion | C50: x | D50: x

Sheet Techniques
A1: ID | B1: Name | C1: Categories
C2: (1) data/memory structure | D2: (2) algorithm implementation | E2: (4) arithmetic/logic operations | F2: (4) loops
A3: T4 | B3: Cascaded function calls | F3: x
A4: T5 | B4: Row-major accessing | D4: x
A5: T7 | B5: Common subexpression elimination | C5: x | D5: x
A6: T8 | B6: Mapping structures | C6: x | D6: x
A7: T9 | B7: Dead code elimination | D7: x
A8: T10 | B8: Exception handling | D8: x | F8: x
A9: T11 | B9: Global variables within loops | C9: x | F9: x
A10: T12 | B10: Function inlining | D10: x
A11: T13 | B11: Global variables within loops | C11: x | F11: x
A12: T16 | B12: Division by a power-of-two denominator | E12: x
A13: T17 | B13: Multiplication by a power-of-two factor | E13: x
A14: T19 | B14: Loop countdown | D14: x | F14: x
A15: T20 | B15: Loop unrolling | D15: x | F15: x
A16: T25 | B16: Linear search | D16: x | F16: x
A17: T26 | B17: Invariant if statements within loops | D17: x | F17: x
A18: T28 | B18: Loop fission | F18: x
A19: T29 | B19: Range check | E19: x
A20: T31 | B20: Buffer IO | D20: x
A21: T32 | B21: Look-up table | D21: x
A22: T33 | B22: Tail function calls | D22: x
A23: T36 | B23: Loop exit using break | F23: x
A24: T40 | B24: Loop jamming | F24: x
A25: T44 | B25: Lazy evaluation | E25: x
A26: T49 | B26: Sentinels | D26: x
A27: T50 | B27: Wasted iterations | D27: x
A28: T51 | B28: Coarsening recursion | D28: x

Sheet C Impact of Technique
A1: Technique | B1: Optimization | C1: Test | D1: Time (s) | E1: Power | H1: Consumption (with baseline) | K1: Consumption (without baseline) | N1: Impact of Technique ((Test2-Test1)/Test1%)
E2: HDD (w) | F2: CPU (w) | G2: DUT (w) | H2: HDD (J) | I2: CPU (J) | J2: DUT (J) | K2: HDD (J) | L2: CPU (J) | M2: DUT (J) | N2: Time (s) | O2: HDD (J) | P2: CPU (J) | Q2: DUT (J)
A3: T4 | B3: O0 | C3: Test1 | D3: 4.711 | E3: 1.86 | F3: 22.25 | G3: 140.24 | H3: 8.76246 | I3: 104.81975 | J3: 660.67064 | K3: 6.78384 | L3: 102.08737 | M3: 221.55833 | N3: =(D4-D3)/D3 -> -0.22224581 | O3: =(K4-K3)/K3 -> -0.21684474 | P3: =(L4-L3)/L3 -> -0.32094558 | Q3: =(M4-M3)/M3 -> -0.35735641
C4: Test2 | D4: 3.664 | E4: 1.87 | F4: 19.5 | G4: 132.07 | H4: 6.85168 | I4: 71.448 | J4: 483.90448 | K4: 5.3128 | L4: 69.32288 | M4: 142.38304
B5: O3 | C5: Test1 | D5: 3.14 | E5: 1.87 | F5: 19.12 | G5: 131 | H5: 5.8718 | I5: 60.0368 | J5: 411.34 | K5: 4.553 | L5: 58.2156 | M5: 118.6606 | N5: =(D6-D5)/D5 -> -0.66592357 | O5: =(K6-K5)/K5 -> -0.64518779 | P5: =(L6-L5)/L5 -> -0.79187795 | Q5: =(M6-M5)/M5 -> -0.8203643
C6: Test2 | D6: 1.049 | E6: 1.96 | F6: 12.13 | G6: 113.52 | H6: 2.05604 | I6: 12.72437 | J6: 119.08248 | K6: 1.61546 | L6: 12.11595 | M6: 21.31568
A7: T7 | B7: O0 | C7: Test1 | D7: 2.094 | E7: 1.93 | F7: 15.48 | G7: 121.16 | H7: 4.04142 | I7: 32.41512 | J7: 253.70904 | K7: 3.16194 | L7: 31.2006 | M7: 63.53196 | N7: =(D8-D7)/D7 -> -0.50047755 | O7: =(K8-K7)/K7 -> -0.48393708 | P7: =(L8-L7)/L7 -> -0.50986455 | Q7: =(M8-M7)/M7 -> -0.57028557
C8: Test2 | D8: 1.046 | E8: 1.98 | F8: 15.2 | G8: 116.92 | H8: 2.07108 | I8: 15.8992 | J8: 122.29832 | K8: 1.63176 | L8: 15.29252 | M8: 27.3006
B9: O3 | C9: Test1 | D9: 2.093 | E9: 1.94 | F9: 15.4 | G9: 120.98 | H9: 4.06042 | I9: 32.2322 | J9: 253.21114 | K9: 3.18136 | L9: 31.01826 | M9: 63.10395 | N9: =(D10-D9)/D9 -> -0.49976111 | O9: =(K10-K9)/K9 -> -0.48330588 | P9: =(L10-L9)/L9 -> -0.51393792 | Q9: =(M10-M9)/M9 -> -0.54970204
C10: Test2 | D10: 1.047 | E10: 1.99 | F10: 14.98 | G10: 117.96 | H10: 2.08353 | I10: 15.68406 | J10: 123.50412 | K10: 1.64379 | L10: 15.0768 | M10: 28.41558
A11: T8 | B11: O0 | C11: Test1 | D11: 4.711 | E11: 1.83 | F11: 25.14 | G11: 144.2 | H11: 8.62113 | I11: 118.43454 | J11: 679.3262 | K11: 6.64251 | L11: 115.70216 | M11: 243.32315 | N11: =(D12-D11)/D11 -> 0.13797495 | O11: =(K12-K11)/K11 -> 0.20254091 | P11: =(L12-L11)/L11 -> 0.16021551 | Q11: =(M12-M11)/M11 -> 0.185565
C12: Test2 | D12: 5.361 | E12: 1.91 | F12: 25.62 | G12: 146.35 | H12: 10.23951 | I12: 137.34882 | J12: 784.58235 | K12: 7.98789 | L12: 134.23944 | M12: 288.47541
B13: O3 | C13: Test1 | D13: 22.884 | E13: 1.88 | F13: 22.12 | G13: 141.77 | H13: 43.02192 | I13: 506.19408 | J13: 3244.2647 | K13: 33.41064 | L13: 492.92136 | M13: 1126.5793 | N13: =(D14-D13)/D13 -> -0.80401154 | O13: =(K14-K13)/K13 -> -0.79998438 | P13: =(L14-L13)/L13 -> -0.78381217 | Q13: =(M14-M13)/M13 -> -0.79879632
C14: Test2 | D14: 4.485 | E14: 1.91 | F14: 24.34 | G14: 143.09 | H14: 8.56635 | I14: 109.1649 | J14: 641.75865 | K14: 6.68265 | L14: 106.5636 | M14: 226.6719
A15: T9 | B15: O0 | C15: Test1 | D15: 0.524 | E15: 2.04 | F15: 8.95 | G15: 106.49 | H15: 1.06896 | I15: 4.6898 | J15: 55.80076 | K15: 0.84888 | L15: 4.38588 | M15: 7.336 | N15: =(D16-D15)/D15 -> 0 | O15: =(K16-K15)/K15 -> -0.0061728395 | P15: =(L16-L15)/L15 -> -0.089605735 | Q15: =(M16-M15)/M15 -> -0.11428571
C16: Test2 | D16: 0.524 | E16: 2.03 | F16: 8.2 | G16: 104.89 | H16: 1.06372 | I16: 4.2968 | J16: 54.96236 | K16: 0.84364 | L16: 3.99288 | M16: 6.4976
B17: O3 | C17: Test1 | D17: 0.524 | E17: 2.05 | F17: 8.24 | G17: 104.52 | H17: 1.0742 | I17: 4.31776 | J17: 54.76848 | K17: 0.85412 | L17: 4.01384 | M17: 6.30372 | N17: =(D18-D17)/D17 -> -0.0019083969 | O17: =(K18-K17)/K17 -> -0.026401442 | P17: =(L18-L17)/L17 -> -0.013635322 | Q17: =(M18-M17)/M17 -> -0.030946806
C18: Test2 | D18: 0.523 | E18: 2.01 | F18: 8.15 | G18: 104.17 | H18: 1.05123 | I18: 4.26245 | J18: 54.48091 | K18: 0.83157 | L18: 3.95911 | M18: 6.10864
A19: T10 | B19: O0 | C19: Test1 | D19: 76.261 | E19: 1.82 | F19: 27.27 | G19: 154.76 | H19: 138.79502 | I19: 2079.6375 | J19: 11802.152 | K19: 106.7654 | L19: 2035.4061 | M19: 4730.4698 | N19: =(D20-D19)/D19 -> -0.98621838 | O19: =(K20-K19)/K19 -> -0.98493866 | P19: =(L20-L19)/L19 -> -0.99610149 | Q19: =(M20-M19)/M19 -> -0.99694507
C20: Test2 | D20: 1.051 | E20: 1.95 | F20: 8.13 | G20: 106.48 | H20: 2.04945 | I20: 8.54463 | J20: 111.91048 | K20: 1.60803 | L20: 7.93505 | M20: 14.45125
B21: O3 | C21: Test1 | D21: 76.289 | E21: 1.84 | F21: 27.34 | G21: 155 | H21: 140.37176 | I21: 2085.7413 | J21: 11824.795 | K21: 108.33038 | L21: 2041.4936 | M21: 4750.516 | N21: =(D22-D21)/D21 -> -0.99310517 | O21: =(K22-K21)/K21 -> -0.99213406 | P21: =(L22-L21)/L21 -> -0.99811397 | Q21: =(M22-M21)/M21 -> -0.99870452
C22: Test2 | D22: 0.526 | E22: 2.04 | F22: 7.9 | G22: 104.43 | H22: 1.07304 | I22: 4.1554 | J22: 54.93018 | K22: 0.85212 | L22: 3.85032 | M22: 6.1542
A23: T11 | B23: O0 | C23: Test1 | D23: 2.094 | E23: 1.94 | F23: 17.4 | G23: 126.84 | H23: 4.06236 | I23: 36.4356 | J23: 265.60296 | K23: 3.18288 | L23: 35.22108 | M23: 70.4631 | N23: =(D24-D23)/D23 -> -0.00047755492 | O23: =(K24-K23)/K23 -> -0.00047755492 | P23: =(L24-L23)/L23 -> -0.018899193 | Q23: =(M24-M23)/M23 -> -0.048597209
C24: Test2 | D24: 2.093 | E24: 1.94 | F24: 17.09 | G24: 125.22 | H24: 4.06042 | I24: 35.76937 | J24: 262.08546 | K24: 3.18136 | L24: 34.55543 | M24: 67.03879
B25: O3 | C25: Test1 | D25: 1.047 | E25: 2.01 | F25: 13.58 | G25: 116.79 | H25: 2.10447 | I25: 14.21826 | J25: 122.27913 | K25: 1.66473 | L25: 13.611 | M25: 24.7092 | N25: =(D26-D25)/D25 -> 0 | O25: =(K26-K25)/K25 -> -0.0062893082 | P25: =(L26-L25)/L25 -> -0.22230769 | Q25: =(M26-M25)/M25 -> -0.27457627
C26: Test2 | D26: 1.047 | E26: 2 | F26: 10.69 | G26: 110.3 | H26: 2.094 | I26: 11.19243 | J26: 115.4841 | K26: 1.65426 | L26: 10.58517 | M26: 17.92464
A27: T12 | B27: O0 | C27: Test1 | D27: 1.047 | E27: 2 | F27: 13.98 | G27: 116.33 | H27: 2.094 | I27: 14.63706 | J27: 121.79751 | K27: 1.65426 | L27: 14.0298 | M27: 23.52609 | N27: =(D28-D27)/D27 -> 0 | O27: =(K28-K27)/K27 -> 0 | P27: =(L28-L27)/L27 -> -0.25671642 | Q27: =(M28-M27)/M27 -> -0.20516244
C28: Test2 | D28: 1.047 | E28: 2 | F28: 10.54 | G28: 111.73 | H28: 2.094 | I28: 11.03538 | J28: 116.98131 | K28: 1.65426 | L28: 10.42812 | M28: 18.69942
B29: O3 | C29: Test1 | D29: 0.594 | E29: 2.08 | F29: 8.97 | G29: 107.23 | H29: 1.23552 | I29: 5.32818 | J29: 63.69462 | K29: 0.98604 | L29: 4.98366 | M29: 7.94178 | N29: =(D30-D29)/D29 -> 0.028619529 | O29: =(K30-K29)/K29 -> 0.028619529 | P29: =(L30-L29)/L29 -> 0.021263489 | Q29: =(M30-M29)/M29 -> 0.075549814
C30: Test2 | D30: 0.611 | E30: 2.08 | F30: 8.91 | G30: 107.85 | H30: 1.27088 | I30: 5.44401 | J30: 65.89635 | K30: 1.01426 | L30: 5.08963 | M30: 8.54178
A31: T13 | B31: O0 | C31: Test1 | D31: 8.376 | E31: 1.92 | F31: 23.19 | G31: 141.44 | H31: 16.08192 | I31: 194.23944 | J31: 1184.7014 | K31: 12.564 | L31: 189.38136 | M31: 418.63248 | N31: =(D32-D31)/D31 -> 0.0054918816 | O31: =(K32-K31)/K31 -> 0.0054918816 | P31: =(L32-L31)/L31 -> -0.0056258969 | Q31: =(M32-M31)/M31 -> -0.0051705974
C32: Test2 | D32: 8.422 | E32: 1.92 | F32: 22.94 | G32: 140.91 | H32: 16.17024 | I32: 193.20068 | J32: 1186.744 | K32: 12.633 | L32: 188.31592 | M32: 416.4679
B33: O3 | C33: Test1 | D33: 6.281 | E33: 1.92 | F33: 22.2 | G33: 138.38 | H33: 12.05952 | I33: 139.4382 | J33: 869.16478 | K33: 9.4215 | L33: 135.79522 | M33: 294.70452 | N33: =(D34-D33)/D33 -> -0.079605158 | O33: =(K34-K33)/K33 -> -0.079605158 | P33: =(L34-L33)/L33 -> -0.13154233 | Q33: =(M34-M33)/M33 -> -0.11118733
C34: Test2 | D34: 5.781 | E34: 1.92 | F34: 20.98 | G34: 136.77 | H34: 11.09952 | I34: 121.28538 | J34: 790.66737 | K34: 8.6715 | L34: 117.9324 | M34: 261.93711
A35: T16 | B35: O0 | C35: Test1 | D35: 1.047 | E35: 1.96 | F35: 10.33 | G35: 110.49 | H35: 2.05212 | I35: 11.91486 | J35: 117.61998 | K35: 1.61238 | L35: 11.3076 | M35: 20.51073 | N35: =(D36-D35)/D35 -> -0.35052531 | O35: =(K36-K35)/K35 -> 0 | P35: =(L36-L35)/L35 -> -0.097222222 | Q35: =(M36-M35)/M35 -> -0.094946401
C36: Test2 | D36: 0.68 | E36: 2.07 | F36: 8.61 | G36: 105.35 | H36: 2.05212 | I36: 10.81551 | J36: 115.68303 | K36: 1.61238 | L36: 10.20825 | M36: 18.56331
B37: O3 | C37: Test1 | D37: 1.047 | E37: 1.96 | F37: 11.38 | G37: 112.34 | H37: 1.3243 | I37: 5.67188 | J37: 68.67626 | K37: 1.05298 | L37: 5.2972 | M37: 8.7533 | N37: =(D38-D37)/D37 -> -0.38299904 | O37: =(K38-K37)/K37 -> 0.020019374 | P37: =(L38-L37)/L37 -> 0.0062901155 | Q37: =(M38-M37)/M37 -> 0.027830647
C38: Test2 | D38: 0.646 | E38: 2.05 | F38: 8.78 | G38: 106.31 | H38: 1.35252 | I38: 5.71506 | J38: 70.49016 | K38: 1.07406 | L38: 5.33052 | M38: 8.99691
A39: T17 | B39: O0 | C39: Test1 | D39: 1.046 | E39: 1.94 | F39: 10.4 | G39: 109.59 | H39: 2.02924 | I39: 10.8784 | J39: 114.63114 | K39: 1.58992 | L39: 10.27172 | M39: 18.54558 | N39: =(D40-D39)/D39 -> 0.00095602294 | O39: =(K40-K39)/K39 -> 0.033882208 | P39: =(L40-L39)/L39 -> 0.030515824 | Q39: =(M40-M39)/M39 -> 0.055717858
C40: Test2 | D40: 1.047 | E40: 1.99 | F40: 10.69 | G40: 110.56 | H40: 2.08353 | I40: 11.19243 | J40: 115.75632 | K40: 1.64379 | L40: 10.58517 | M40: 19.5789
...

Sheet C Technique results
B1: Optimization level O0 | F1: Optimization level O3
A2: Technique | B2: Standard (J) | C2: Efficient (J) | D2: Impact (%) | E2: Effect size | F2: Standard (J) | G2: Efficient (J) | H2: Impact (%) | I2: Effect size | J2: Average impact (%)
A3: T4 | B3: {=INDIRECT("'C Impact of Technique'!M" & 3 + (ROW(A1)-1)*4)} -> 221.55833 | C3: {=INDIRECT("'C Impact of Technique'!M" & 4 + (ROW(A1)-1)*4)} -> 142.38304 | D3: {=INDIRECT("'C Impact of Technique'!Q" & 3 + (ROW(A1)-1)*4)*100} -> -35.735641 | E3: large | F3: {=INDIRECT("'C Impact of Technique'!M" & 5 + (ROW(A1)-1)*4)} -> 118.6606 | G3: {=INDIRECT("'C Impact of Technique'!M" & 6 + (ROW(A1)-1)*4)} -> 21.31568 | H3: {=INDIRECT("'C Impact of Technique'!Q" & 5 + (ROW(D1)-1)*4)*100} -> -82.03643 | I3: large | J3: =AVERAGE(D3,H3) -> -58.886036 | N3: Optimization level O0 | R3: Optimization level O3
A4: T7 | B4: {=INDIRECT("'C Impact of Technique'!M" & 3 + (ROW(A2)-1)*4)} -> 63.53196 | C4: {=INDIRECT("'C Impact of Technique'!M" & 4 + (ROW(A2)-1)*4)} -> 27.3006 | D4: {=INDIRECT("'C Impact of Technique'!Q" & 3 + (ROW(A2)-1)*4)*100} -> -57.028557 | E4: large | F4: {=INDIRECT("'C Impact of Technique'!M" & 5 + (ROW(A2)-1)*4)} -> 63.10395 | G4: {=INDIRECT("'C Impact of Technique'!M" & 6 + (ROW(A2)-1)*4)} -> 28.41558 | H4: {=INDIRECT("'C Impact of Technique'!Q" & 5 + (ROW(D2)-1)*4)*100} -> -54.970204 | I4: medium | J4: =AVERAGE(D4,H4) -> -55.99938 | N4: Impact | O4: Techniques | R4: Impact | S4: Techniques
A5: T8 | B5: {=INDIRECT("'C Impact of Technique'!M" & 3 + (ROW(A3)-1)*4)} -> 243.32315 | C5: {=INDIRECT("'C Impact of Technique'!M" & 4 + (ROW(A3)-1)*4)} -> 288.47541 | D5: {=INDIRECT("'C Impact of Technique'!Q" & 3 + (ROW(A3)-1)*4)*100} -> 18.5565 | E5: large | F5: {=INDIRECT("'C Impact of Technique'!M" & 5 + (ROW(A3)-1)*4)} -> 1126.5793 | G5: {=INDIRECT("'C Impact of Technique'!M" & 6 + (ROW(A3)-1)*4)} -> 226.6719 | H5: {=INDIRECT("'C Impact of Technique'!Q" & 5 + (ROW(D3)-1)*4)*100} -> -79.879632 | I5: large | J5: =AVERAGE(D5,H5) -> -30.661566 | N5: <= -75 | O5: {=_xlfn.TEXTJOIN(", ", TRUE, IF(D3:D25 <= -75, A3:A25, ""))} -> T10 | R5: <= -75 | S5: {=_xlfn.TEXTJOIN(", ", TRUE, IF(H3:H25 <= -75, A3:A25, ""))} -> T4, T8, T10, T26, T40
A6: T9 | B6: {=INDIRECT("'C Impact of Technique'!M" & 3 + (ROW(A4)-1)*4)} -> 7.336 | C6: {=INDIRECT("'C Impact of Technique'!M" & 4 + (ROW(A4)-1)*4)} -> 6.4976 | D6: {=INDIRECT("'C Impact of Technique'!Q" & 3 + (ROW(A4)-1)*4)*100} -> -11.428571 | E6: large | F6: {=INDIRECT("'C Impact of Technique'!M" & 5 + (ROW(A4)-1)*4)} -> 6.30372 | G6: {=INDIRECT("'C Impact of Technique'!M" & 6 + (ROW(A4)-1)*4)} -> 6.10864 | H6: {=INDIRECT("'C Impact of Technique'!Q" & 5 + (ROW(D4)-1)*4)*100} -> -3.0946806 | I6: large | J6: =AVERAGE(D6,H6) -> -7.261626 | N6: > -75 & <= -25 | O6: {=_xlfn.TEXTJOIN(", ", TRUE, IF((D3:D25 > -75) * (D3:D25 <= -25), A3:A25, ""))} -> T4, T7, T20, T49 | R6: > -75 & <= -25 | S6: {=_xlfn.TEXTJOIN(", ", TRUE, IF((H3:H25 > -75) * (H3:H25 <= -25), A3:A25, ""))} -> T7, T11
A7: T10 | B7: {=INDIRECT("'C Impact of Technique'!M" & 3 + (ROW(A5)-1)*4)} -> 4730.4698 | C7: {=INDIRECT("'C Impact of Technique'!M" & 4 + (ROW(A5)-1)*4)} -> 14.45125 | D7: {=INDIRECT("'C Impact of Technique'!Q" & 3 + (ROW(A5)-1)*4)*100} -> -99.694507 | E7: medium | F7: {=INDIRECT("'C Impact of Technique'!M" & 5 + (ROW(A5)-1)*4)} -> 4750.516 | G7: {=INDIRECT("'C Impact of Technique'!M" & 6 + (ROW(A5)-1)*4)} -> 6.1542 | H7: {=INDIRECT("'C Impact of Technique'!Q" & 5 + (ROW(D5)-1)*4)*100} -> -99.870452 | I7: small~ | J7: =AVERAGE(D7,H7) -> -99.78248 | N7: > -25 & <= -3 | O7: {=_xlfn.TEXTJOIN(", ", TRUE, IF((D3:D25 > -25) * (D3:D25 <= -3), A3:A25, ""))} -> T9, T11, T12, T16, T25, T29, T32, T36, T40, T44 | R7: > -25 & <= -3 | S7: {=_xlfn.TEXTJOIN(", ", TRUE, IF((H3:H25 > -25) * (H3:H25 <= -3), A3:A25, ""))} -> T9, T13, T17, T25, T28
A8: T11 | B8: {=INDIRECT("'C Impact of Technique'!M" & 3 + (ROW(A6)-1)*4)} -> 70.4631 | C8: {=INDIRECT("'C Impact of Technique'!M" & 4 + (ROW(A6)-1)*4)} -> 67.03879 | D8: {=INDIRECT("'C Impact of Technique'!Q" & 3 + (ROW(A6)-1)*4)*100} -> -4.8597209 | E8: large | F8: {=INDIRECT("'C Impact of Technique'!M" & 5 + (ROW(A6)-1)*4)} -> 24.7092 | G8: {=INDIRECT("'C Impact of Technique'!M" & 6 + (ROW(A6)-1)*4)} -> 17.92464 | H8: {=INDIRECT("'C Impact of Technique'!Q" & 5 + (ROW(D6)-1)*4)*100} -> -27.457627 | I8: large | J8: =AVERAGE(D8,H8) -> -16.158674 | N8: > -3 & < 3 | O8: {=_xlfn.TEXTJOIN(", ", TRUE, IF((D3:D25 > -3) * (D3:D25 < 3), A3:A25, ""))} -> T13, T26 | R8: > -3 & < 3 | S8: {=_xlfn.TEXTJOIN(", ", TRUE, IF((H3:H25 > -3) * (H3:H25 < 3), A3:A25, ""))} -> T16
A9: T12 | B9: {=INDIRECT("'C Impact of Technique'!M" & 3 + (ROW(A7)-1)*4)} -> 23.52609 | C9: {=INDIRECT("'C Impact of Technique'!M" & 4 + (ROW(A7)-1)*4)} -> 18.69942 | D9: {=INDIRECT("'C Impact of Technique'!Q" & 3 + (ROW(A7)-1)*4)*100} -> -20.516244 | E9: large | F9: {=INDIRECT("'C Impact of Technique'!M" & 5 + (ROW(A7)-1)*4)} -> 7.94178 | G9: {=INDIRECT("'C Impact of Technique'!M" & 6 + (ROW(A7)-1)*4)} -> 8.54178 | H9: {=INDIRECT("'C Impact of Technique'!Q" & 5 + (ROW(D7)-1)*4)*100} -> 7.5549814 | I9: large | J9: =AVERAGE(D9,H9) -> -6.4806313 | N9: >= 3 & < 25 | O9: {=_xlfn.TEXTJOIN(", ", TRUE, IF((D3:D25 >= 3) * (D3:D25 < 25), A3:A25, ""))} -> T8, T17, T33 | R9: >= 3 & < 25 | S9: {=_xlfn.TEXTJOIN(", ", TRUE, IF((H3:H25 >= 3) * (H3:H25 < 25), A3:A25, ""))} -> T12, T19, T29, T32, T33, T36, T44
A10: T13 | B10: {=INDIRECT("'C Impact of Technique'!M" & 3 + (ROW(A8)-1)*4)} -> 418.63248 | C10: {=INDIRECT("'C Impact of Technique'!M" & 4 + (ROW(A8)-1)*4)} -> 416.4679 | D10: {=INDIRECT("'C Impact of Technique'!Q" & 3 + (ROW(A8)-1)*4)*100} -> -0.51705974 | E10: large | F10: {=INDIRECT("'C Impact of Technique'!M" & 5 + (ROW(A8)-1)*4)} -> 294.70452 | G10: {=INDIRECT("'C Impact of Technique'!M" & 6 + (ROW(A8)-1)*4)} -> 261.93711 | H10: {=INDIRECT("'C Impact of Technique'!Q" & 5 + (ROW(D8)-1)*4)*100} -> -11.118733 | I10: small~ | J10: =AVERAGE(D10,H10) -> -5.8178966 | N10: >= 25 & < 75 | O10: {=_xlfn.TEXTJOIN(", ", TRUE, IF((D3:D25 >= 25) * (D3:D25 < 75), A3:A25, ""))} -> T19 | R10: >= 25 & < 75 | S10: {=_xlfn.TEXTJOIN(", ", TRUE, IF((H3:H25 >= 25) * (H3:H25 < 75), A3:A25, ""))} -> T20
A11: T16 | B11: {=INDIRECT("'C Impact of Technique'!M" & 3 + (ROW(A9)-1)*4)} -> 20.51073 | C11: {=INDIRECT("'C Impact of Technique'!M" & 4 + (ROW(A9)-1)*4)} -> 18.56331 | D11: {=INDIRECT("'C Impact of Technique'!Q" & 3 + (ROW(A9)-1)*4)*100} -> -9.4946401 | E11: small~ | F11: {=INDIRECT("'C Impact of Technique'!M" & 5 + (ROW(A9)-1)*4)} -> 8.7533 | G11: {=INDIRECT("'C Impact of Technique'!M" & 6 + (ROW(A9)-1)*4)} -> 8.99691 | H11: {=INDIRECT("'C Impact of Technique'!Q" & 5 + (ROW(D9)-1)*4)*100} -> 2.7830647 | I11: large | J11: =AVERAGE(D11,H11) -> -3.3557877 | N11: >= 75 | O11: {=_xlfn.TEXTJOIN(", ", TRUE, IF(D3:D25 >= 75, A3:A25, ""))} -> T28, T31 | R11: >= 75 | S11: {=_xlfn.TEXTJOIN(", ", TRUE, IF(H3:H25 >= 75, A3:A25, ""))} -> T31, T49
A12: T17 | B12: {=INDIRECT("'C Impact of Technique'!M" & 3 + (ROW(A10)-1)*4)} -> 18.54558 | C12: {=INDIRECT("'C Impact of Technique'!M" & 4 + (ROW(A10)-1)*4)} -> 19.5789 | D12: {=INDIRECT("'C Impact of Technique'!Q" & 3 + (ROW(A10)-1)*4)*100} -> 5.5717858 | E12: medium | F12: {=INDIRECT("'C Impact of Technique'!M" & 5 + (ROW(A10)-1)*4)} -> 10.66544 | G12: {=INDIRECT("'C Impact of Technique'!M" & 6 + (ROW(A10)-1)*4)} -> 9.18 | H12: {=INDIRECT("'C Impact of Technique'!Q" & 5 + (ROW(D10)-1)*4)*100} -> -13.927602 | I12: small~ | J12: =AVERAGE(D12,H12) -> -4.1779079
A13: T19 | B13: {=INDIRECT("'C Impact of Technique'!M" & 3 + (ROW(A11)-1)*4)} -> 673.59663 | C13: {=INDIRECT("'C Impact of Technique'!M" & 4 + (ROW(A11)-1)*4)} -> 887.26553 | D13: {=INDIRECT("'C Impact of Technique'!Q" & 3 + (ROW(A11)-1)*4)*100} -> 31.720601 | E13: small~ | F13: {=INDIRECT("'C Impact of Technique'!M" & 5 + (ROW(A11)-1)*4)} -> 46.1423 | G13: {=INDIRECT("'C Impact of Technique'!M" & 6 + (ROW(A11)-1)*4)} -> 50.24322 | H13: {=INDIRECT("'C Impact of Technique'!Q" & 5 + (ROW(D11)-1)*4)*100} -> 8.88755 | I13: small | J13: =AVERAGE(D13,H13) -> 20.304076
A14: T20 | B14: {=INDIRECT("'C Impact of Technique'!M" & 3 + (ROW(A12)-1)*4)} -> 436.98078 | C14: {=INDIRECT("'C Impact of Technique'!M" & 4 + (ROW(A12)-1)*4)} -> 145.371 | D14: {=INDIRECT("'C Impact of Technique'!Q" & 3 + (ROW(A12)-1)*4)*100} -> -66.732862 | E14: large | F14: {=INDIRECT("'C Impact of Technique'!M" & 5 + (ROW(A12)-1)*4)} -> 26.86602 | G14: {=INDIRECT("'C Impact of Technique'!M" & 6 + (ROW(A12)-1)*4)} -> 44.18754 | H14: {=INDIRECT("'C Impact of Technique'!Q" & 5 + (ROW(D12)-1)*4)*100} -> 64.473711 | I14: large | J14: =AVERAGE(D14,H14) -> -1.1295756
A15: T25 | B15: {=INDIRECT("'C Impact of Technique'!M" & 3 + (ROW(A13)-1)*4)} -> 900.2326 | C15: {=INDIRECT("'C Impact of Technique'!M" & 4 + (ROW(A13)-1)*4)} -> 729.2229 | D15: {=INDIRECT("'C Impact of Technique'!Q" & 3 + (ROW(A13)-1)*4)*100} -> -18.996168 | E15: large | F15: {=INDIRECT("'C Impact of Technique'!M" & 5 + (ROW(A13)-1)*4)} -> 192.984 | G15: {=INDIRECT("'C Impact of Technique'!M" & 6 + (ROW(A13)-1)*4)} -> 145.28371 | H15: {=INDIRECT("'C Impact of Technique'!Q" & 5 + (ROW(D13)-1)*4)*100} -> -24.717225 | I15: large | J15: =AVERAGE(D15,H15) -> -21.856697
A16: T26 | B16: {=INDIRECT("'C Impact of Technique'!M" & 3 + (ROW(A14)-1)*4)} -> 946.51452 | C16: {=INDIRECT("'C Impact of Technique'!M" & 4 + (ROW(A14)-1)*4)} -> 944.87532 | D16: {=INDIRECT("'C Impact of Technique'!Q" & 3 + (ROW(A14)-1)*4)*100} -> -0.17318276 | E16: large | F16: {=INDIRECT("'C Impact of Technique'!M" & 5 + (ROW(A14)-1)*4)} -> 238.577 | G16: {=INDIRECT("'C Impact of Technique'!M" & 6 + (ROW(A14)-1)*4)} -> 26.21604 | H16: {=INDIRECT("'C Impact of Technique'!Q" & 5 + (ROW(D14)-1)*4)*100} -> -89.011497 | I16: large | J16: =AVERAGE(D16,H16) -> -44.59234
A17: T28 | B17: {=INDIRECT("'C Impact of Technique'!M" & 3 + (ROW(A15)-1)*4)} -> 344.20188 | C17: {=INDIRECT("'C Impact of Technique'!M" & 4 + (ROW(A15)-1)*4)} -> 693.75799 | D17: {=INDIRECT("'C Impact of Technique'!Q" & 3 + (ROW(A15)-1)*4)*100} -> 101.55555 | E17: small~ | F17: {=INDIRECT("'C Impact of Technique'!M" & 5 + (ROW(A15)-1)*4)} -> 35.9373 | G17: {=INDIRECT("'C Impact of Technique'!M" & 6 + (ROW(A15)-1)*4)} -> 33.65609 | H17: {=INDIRECT("'C Impact of Technique'!Q" & 5 + (ROW(D15)-1)*4)*100} -> -6.3477501 | I17: large | J17: =AVERAGE(D17,H17) -> 47.6039
A18: T29 | B18: {=INDIRECT("'C Impact of Technique'!M" & 3 + (ROW(A16)-1)*4)} -> 14.3439 | C18: {=INDIRECT("'C Impact of Technique'!M" & 4 + (ROW(A16)-1)*4)} -> 13.90416 | D18: {=INDIRECT("'C Impact of Technique'!Q" & 3 + (ROW(A16)-1)*4)*100} -> -3.0656934 | E18: large | F18: {=INDIRECT("'C Impact of Technique'!M" & 5 + (ROW(A16)-1)*4)} -> 6.4452 | G18: {=INDIRECT("'C Impact of Technique'!M" & 6 + (ROW(A16)-1)*4)} -> 6.75716 | H18: {=INDIRECT("'C Impact of Technique'!Q" & 5 + (ROW(D16)-1)*4)*100} -> 4.8401912 | I18: medium | J18: =AVERAGE(D18,H18) -> 0.88724886
A19: T31 | B19: {=INDIRECT("'C Impact of Technique'!M" & 3 + (ROW(A17)-1)*4)} -> 978.7239 | C19: {=INDIRECT("'C Impact of Technique'!M" & 4 + (ROW(A17)-1)*4)} -> 2084.8756 | D19: {=INDIRECT("'C Impact of Technique'!Q" & 3 + (ROW(A17)-1)*4)*100} -> 113.0198 | E19: small~ | F19: {=INDIRECT("'C Impact of Technique'!M" & 5 + (ROW(A17)-1)*4)} -> 756.50404 | G19: {=INDIRECT("'C Impact of Technique'!M" & 6 + (ROW(A17)-1)*4)} -> 1718.9779 | H19: {=INDIRECT("'C Impact of Technique'!Q" & 5 + (ROW(D17)-1)*4)*100} -> 127.22654 | I19: small~ | J19: =AVERAGE(D19,H19) -> 120.12317
A20: T32 | B20: {=INDIRECT("'C Impact of Technique'!M" & 3 + (ROW(A18)-1)*4)} -> 18.96117 | C20: {=INDIRECT("'C Impact of Technique'!M" & 4 + (ROW(A18)-1)*4)} -> 15.87252 | D20: {=INDIRECT("'C Impact of Technique'!Q" & 3 + (ROW(A18)-1)*4)*100} -> -16.289343 | E20: large | F20: {=INDIRECT("'C Impact of Technique'!M" & 5 + (ROW(A18)-1)*4)} -> 7.14212 | G20: {=INDIRECT("'C Impact of Technique'!M" & 6 + (ROW(A18)-1)*4)} -> 7.61896 | H20: {=INDIRECT("'C Impact of Technique'!Q" & 5 + (ROW(D18)-1)*4)*100} -> 6.676449 | I20: large | J20: =AVERAGE(D20,H20) -> -4.8064469
A21: T33 | B21: {=INDIRECT("'C Impact of Technique'!M" & 3 + (ROW(A19)-1)*4)} -> 24.97616 | C21: {=INDIRECT("'C Impact of Technique'!M" & 4 + (ROW(A19)-1)*4)} -> 25.90278 | D21: {=INDIRECT("'C Impact of Technique'!Q" & 3 + (ROW(A19)-1)*4)*100} -> 3.7100179 | E21: large | F21: {=INDIRECT("'C Impact of Technique'!M" & 5 + (ROW(A19)-1)*4)} -> 20.33274 | G21: {=INDIRECT("'C Impact of Technique'!M" & 6 + (ROW(A19)-1)*4)} -> 21.54726 | H21: {=INDIRECT("'C Impact of Technique'!Q" & 5 + (ROW(D19)-1)*4)*100} -> 5.9732235 | I21: small | J21: =AVERAGE(D21,H21) -> 4.8416207
A22: T36 | B22: {=INDIRECT("'C Impact of Technique'!M" & 3 + (ROW(A20)-1)*4)} -> 178.74303 | C22: {=INDIRECT("'C Impact of Technique'!M" & 4 + (ROW(A20)-1)*4)} -> 171.01735 | D22: {=INDIRECT("'C Impact of Technique'!Q" & 3 + (ROW(A20)-1)*4)*100} -> -4.3222273 | E22: small~ | F22: {=INDIRECT("'C Impact of Technique'!M" & 5 + (ROW(A20)-1)*4)} -> 5.29799 | G22: {=INDIRECT("'C Impact of Technique'!M" & 6 + (ROW(A20)-1)*4)} -> 5.83145 | H22: {=INDIRECT("'C Impact of Technique'!Q" & 5 + (ROW(D20)-1)*4)*100} -> 10.069102 | I22: small | J22: =AVERAGE(D22,H22) -> 2.8734372
A23: T40 | B23: {=INDIRECT("'C Impact of Technique'!M" & 3 + (ROW(A21)-1)*4)} -> 625.08848 | C23: {=INDIRECT("'C Impact of Technique'!M" & 4 + (ROW(A21)-1)*4)} -> 542.62944 | D23: {=INDIRECT("'C Impact of Technique'!Q" & 3 + (ROW(A21)-1)*4)*100} -> -13.191579 | E23: large | F23: {=INDIRECT("'C Impact of Technique'!M" & 5 + (ROW(A21)-1)*4)} -> 263.63058 | G23: {=INDIRECT("'C Impact of Technique'!M" & 6 + (ROW(A21)-1)*4)} -> 52.13562 | H23: {=INDIRECT("'C Impact of Technique'!Q" & 5 + (ROW(D21)-1)*4)*100} -> -80.223986 | I23: small | J23: =AVERAGE(D23,H23) -> -46.707783
... A25: T49 | B25: {=INDIRECT("'C Impact of Technique'!M" & 3 + (ROW(A23)-1)*4)} -> 417.29232 | C25: {=INDIRECT("'C Impact of Technique'!M" & 4 + (ROW(A23)-1)*4)} -> 175.72839 | D25: {=INDIRECT("'C Impact of Technique'!Q" & 3 + (ROW(A23)-1)*4)*100} -> -57.88842 | E25: small | F25: {=INDIRECT("'C Impact of Technique'!M" & 5 + (ROW(A23)-1)*4)} -> 7.25401 | G25: {=INDIRECT("'C Impact of Technique'!M" & 6 + (ROW(A23)-1)*4)} -> 40.78688 | H25: {=INDIRECT("'C Impact of Technique'!Q" & 5 + (ROW(D23)-1)*4)*100} -> 462.26666 | I25: medium | J25: =AVERAGE(D25,H25) -> 202.18912
D32: Optimization level O0 | I32: Optimization level O3
D33: Impact | E33: Average | F33: Min | G33: Max | I33: Impact | J33: Average | K33: Min | L33: Max
D34: Reduction | E34: {=AVERAGE(_xlfn._xlws.FILTER($D$3:$D$25, ISNUMBER(MATCH($A$3:$A$25, _xlfn.TEXTSPLIT(_xlfn.TEXTJOIN(", ", TRUE, O5:O7), ", "), 0))))} -> -28.8259 | F34: {=MIN(_xlfn._xlws.FILTER($D$3:$D$25, ISNUMBER(MATCH($A$3:$A$25, _xlfn.TEXTSPLIT(_xlfn.TEXTJOIN(", ", TRUE, O5:O7), ", "), 0))))} -> -99.694507 | G34: {=MAX(_xlfn._xlws.FILTER($D$3:$D$25, ISNUMBER(MATCH($A$3:$A$25, _xlfn.TEXTSPLIT(_xlfn.TEXTJOIN(", ", TRUE, O5:O7), ", "), 0))))} -> -3.0656934 | I34: Reduction | J34: {=AVERAGE(_xlfn._xlws.FILTER($H$3:$H$25, ISNUMBER(MATCH($A$3:$A$25, _xlfn.TEXTSPLIT(_xlfn.TEXTJOIN(", ", TRUE, S5:S7), ", "), 0))))} -> -47.721318 | K34: {=MIN(_xlfn._xlws.FILTER($H$3:$H$25, ISNUMBER(MATCH($A$3:$A$25, _xlfn.TEXTSPLIT(_xlfn.TEXTJOIN(", ", TRUE, S5:S7), ", "), 0))))} -> -99.870452 | L34: {=MAX(_xlfn._xlws.FILTER($H$3:$H$25, ISNUMBER(MATCH($A$3:$A$25, _xlfn.TEXTSPLIT(_xlfn.TEXTJOIN(", ", TRUE, S5:S7), ", "), 0))))} -> -3.0946806
D35: No impact | E35: {=AVERAGE(_xlfn._xlws.FILTER($D$3:$D$25, ISNUMBER(MATCH($A$3:$A$25, _xlfn.TEXTSPLIT(_xlfn.TEXTJOIN(", ", TRUE, O8), ", "), 0))))} -> -0.34512125 | F35: {=MIN(_xlfn._xlws.FILTER($D$3:$D$25, ISNUMBER(MATCH($A$3:$A$25, _xlfn.TEXTSPLIT(_xlfn.TEXTJOIN(", ", TRUE, O8), ", "), 0))))} -> -0.51705974 | G35: {=MAX(_xlfn._xlws.FILTER($D$3:$D$25, ISNUMBER(MATCH($A$3:$A$25, _xlfn.TEXTSPLIT(_xlfn.TEXTJOIN(", ", TRUE, O8), ", "), 0))))} -> -0.17318276 | I35: No impact | J35: {=AVERAGE(_xlfn._xlws.FILTER($H$3:$H$25, ISNUMBER(MATCH($A$3:$A$25, _xlfn.TEXTSPLIT(_xlfn.TEXTJOIN(", ", TRUE, S8), ", "), 0))))} -> 2.7830647 | K35: {=MIN(_xlfn._xlws.FILTER($H$3:$H$25, ISNUMBER(MATCH($A$3:$A$25, _xlfn.TEXTSPLIT(_xlfn.TEXTJOIN(", ", TRUE, S8), ", "), 0))))} -> 2.7830647 | L35: {=MAX(_xlfn._xlws.FILTER($H$3:$H$25, ISNUMBER(MATCH($A$3:$A$25, _xlfn.TEXTSPLIT(_xlfn.TEXTJOIN(", ", TRUE, S8), ", "), 0))))} -> 2.7830647
D36: Increase | E36: {=AVERAGE(_xlfn._xlws.FILTER($D$3:$D$25, ISNUMBER(MATCH($A$3:$A$25, _xlfn.TEXTSPLIT(_xlfn.TEXTJOIN(", ", TRUE, O9:O11), ", "), 0))))} -> 45.689042 | F36: {=MIN(_xlfn._xlws.FILTER($D$3:$D$25, ISNUMBER(MATCH($A$3:$A$25, _xlfn.TEXTSPLIT(_xlfn.TEXTJOIN(", ", TRUE, O9:O11), ", "), 0))))} -> 3.7100179 | G36: {=MAX(_xlfn._xlws.FILTER($D$3:$D$25, ISNUMBER(MATCH($A$3:$A$25, _xlfn.TEXTSPLIT(_xlfn.TEXTJOIN(", ", TRUE, O9:O11), ", "), 0))))} -> 113.0198 | I36: Increase | J36: {=AVERAGE(_xlfn._xlws.FILTER($H$3:$H$25, ISNUMBER(MATCH($A$3:$A$25, _xlfn.TEXTSPLIT(_xlfn.TEXTJOIN(", ", TRUE, S9:S11), ", "), 0))))} -> 71.325412 | K36: {=MIN(_xlfn._xlws.FILTER($H$3:$H$25, ISNUMBER(MATCH($A$3:$A$25, _xlfn.TEXTSPLIT(_xlfn.TEXTJOIN(", ", TRUE, S9:S11), ", "), 0))))} -> 4.8401912 | L36: {=MAX(_xlfn._xlws.FILTER($H$3:$H$25, ISNUMBER(MATCH($A$3:$A$25, _xlfn.TEXTSPLIT(_xlfn.TEXTJOIN(", ", TRUE, S9:S11), ", "), 0))))} -> 462.26666

Sheet C Impact of Optimization
A1: Technique | B1: Test | C1: Optimization | D1: Time (s) | E1: Power | H1: Consumption (with baseline) | K1: Consumption (without baseline) | N1: Impact of Optimization (O3-O0)/O0%
E2: HDD (w) | F2: CPU (w) | G2: DUT (w) | H2: HDD (J) | I2: CPU (J) | J2: DUT (J) | K2: HDD (J) | L2: CPU (J) | M2: DUT (J) | N2: Time (s) | O2: HDD (J) | P2: CPU (J) | Q2: DUT (J)
A3: T4 | B3: Test1 | C3: O0 | D3: 4.711 | E3: 1.86 | F3: 22.25 | G3: 140.24 | H3: 8.76246 | I3: 104.81975 | J3: 660.67064 | K3: 6.78384 | L3: 102.08737 | M3: 221.55833 | N3: =(D4-D3)/D3 -> -0.33347485 | O3: =(K4-K3)/K3 -> -0.3288462 | P3: =(L4-L3)/L3 -> -0.42974728 | Q3: =(M4-M3)/M3 -> -0.46442727
C4: O3 | D4: 3.14 | E4: 1.87 | F4: 19.12 | G4: 131 | H4: 5.8718 | I4: 60.0368 | J4: 411.34 | K4: 4.553 | L4: 58.2156 | M4: 118.6606
B5: Test2 | C5: O0 | D5: 3.664 | E5: 1.87 | F5: 19.5 | G5: 132.07 | H5: 6.85168 | I5: 71.448 | J5: 483.90448 | K5: 5.3128 | L5: 69.32288 | M5: 142.38304 | N5: =(D6-D5)/D5 -> -0.71370087 | O5: =(K6-K5)/K5 -> -0.69593058 | P5: =(L6-L5)/L5 -> -0.82522437 | Q5: =(M6-M5)/M5 -> -0.85029341
C6: O3 | D6: 1.049 | E6: 1.96 | F6: 12.13 | G6: 113.52 | H6: 2.05604 | I6: 12.72437 | J6: 119.08248 | K6: 1.61546 | L6: 12.11595 | M6: 21.31568
A7: T7 | B7: Test1 | C7: O0 | D7: 2.094 | E7: 1.93 | F7: 15.48 | G7: 121.16 | H7: 4.04142 | I7: 32.41512 | J7: 253.70904 | K7: 3.16194 | L7: 31.2006 | M7: 63.53196 | N7: =(D8-D7)/D7 -> -0.00047755492 | O7: =(K8-K7)/K7 -> 0.006141799 | P7: =(L8-L7)/L7 -> -0.0058441184 | Q7: =(M8-M7)/M7 -> -0.0067369242
C8: O3 | D8: 2.093 | E8: 1.94 | F8: 15.4 | G8: 120.98 | H8: 4.06042 | I8: 32.2322 | J8: 253.21114 | K8: 3.18136 | L8: 31.01826 | M8: 63.10395
B9: Test2 | C9: O0 | D9: 1.046 | E9: 1.98 | F9: 15.2 | G9: 116.92 | H9: 2.07108 | I9: 15.8992 | J9: 122.29832 | K9: 1.63176 | L9: 15.29252 | M9: 27.3006 | N9: =(D10-D9)/D9 -> 0.00095602294 | O9: =(K10-K9)/K9 -> 0.0073724077 | P9: =(L10-L9)/L9 -> -0.014106243 | Q9: =(M10-M9)/M9 -> 0.040840861
C10: O3 | D10: 1.047 | E10: 1.99 | F10: 14.98 | G10: 117.96 | H10: 2.08353 | I10: 15.68406 | J10: 123.50412 | K10: 1.64379 | L10: 15.0768 | M10: 28.41558
A11: T8 | B11: Test1 | C11: O0 | D11: 4.711 | E11: 1.83 | F11: 25.14 | G11: 144.2 | H11: 8.62113 | I11: 118.43454 | J11: 679.3262 | K11: 6.64251 | L11: 115.70216 | M11: 243.32315 | N11: =(D12-D11)/D11 -> 3.8575674 | O11: =(K12-K11)/K11 -> 4.0298216 | P11: =(L12-L11)/L11 -> 3.2602607 | Q11: =(M12-M11)/M11 -> 3.6299718
C12: O3 | D12: 22.884 | E12: 1.88 | F12: 22.12 | G12: 141.77 | H12: 43.02192 | I12: 506.19408 | J12: 3244.2647 | K12: 33.41064 | L12: 492.92136 | M12: 1126.5793
B13: Test2 | C13: O0 | D13: 5.361 | E13: 1.91 | F13: 25.62 | G13: 146.35 | H13: 10.23951 | I13: 137.34882 | J13: 784.58235 | K13: 7.98789 | L13: 134.23944 | M13: 288.47541 | N13: =(D14-D13)/D13 -> -0.16340235 | O13: =(K14-K13)/K13 -> -0.16340235 | P13: =(L14-L13)/L13 -> -0.20616773 | Q13: =(M14-M13)/M13 -> -0.21424187
C14: O3 | D14: 4.485 | E14: 1.91 | F14: 24.34 | G14: 143.09 | H14: 8.56635 | I14: 109.1649 | J14: 641.75865 | K14: 6.68265 | L14: 106.5636 | M14: 226.6719
A15: T9 | B15: Test1 | C15: O0 | D15: 0.524 | E15: 2.04 | F15: 8.95 | G15: 106.49 | H15: 1.06896 | I15: 4.6898 | J15: 55.80076 | K15: 0.84888 | L15: 4.38588 | M15: 7.336 | N15: =(D16-D15)/D15 -> 0 | O15: =(K16-K15)/K15 -> 0.0061728395 | P15: =(L16-L15)/L15 -> -0.084826762 | Q15: =(M16-M15)/M15 -> -0.14071429
C16: O3 | D16: 0.524 | E16: 2.05 | F16: 8.24 | G16: 104.52 | H16: 1.0742 | I16: 4.31776 | J16: 54.76848 | K16: 0.85412 | L16: 4.01384 | M16: 6.30372
B17: Test2 | C17: O0 | D17: 0.524 | E17: 2.03 | F17: 8.2 | G17: 104.89 | H17: 1.06372 | I17: 4.2968 | J17: 54.96236 | K17: 0.84364 | L17: 3.99288 | M17: 6.4976 | N17: =(D18-D17)/D17 -> -0.0019083969 | O17: =(K18-K17)/K17 -> -0.01430705 | P17: =(L18-L17)/L17 -> -0.0084575544 | Q17: =(M18-M17)/M17 -> -0.059862103
C18: O3 | D18: 0.523 | E18: 2.01 | F18: 8.15 | G18: 104.17 | H18: 1.05123 | I18: 4.26245 | J18: 54.48091 | K18: 0.83157 | L18: 3.95911 | M18: 6.10864
A19: T10 | B19: Test1 | C19: O0 | D19: 76.261 | E19: 1.82 | F19: 27.27 | G19: 154.76 | H19: 138.79502 | I19: 2079.6375 | J19: 11802.152 | K19: 106.7654 | L19: 2035.4061 | M19: 4730.4698 | N19: =(D20-D19)/D19 -> 0.00036716015 | O19: =(K20-K19)/K19 -> 0.01465812 | P19: =(L20-L19)/L19 -> 0.0029908282 | Q19: =(M20-M19)/M19 -> 0.0042376763
C20: O3 | D20: 76.289 | E20: 1.84 | F20: 27.34 | G20: 155 | H20: 140.37176 | I20: 2085.7413 | J20: 11824.795 | K20: 108.33038 | L20: 2041.4936 | M20: 4750.516
B21: Test2 | C21: O0 | D21: 1.051 | E21: 1.95 | F21: 8.13 | G21: 106.48 | H21: 2.04945 | I21: 8.54463 | J21: 111.91048 | K21: 1.60803 | L21: 7.93505 | M21: 14.45125 | N21: =(D22-D21)/D21 -> -0.49952426 | O21: =(K22-K21)/K21 -> -0.47008451 | P21: =(L22-L21)/L21 -> -0.51477054 | Q21: =(M22-M21)/M21 -> -0.57414065
C22: O3 | D22: 0.526 | E22: 2.04 | F22: 7.9 | G22: 104.43 | H22: 1.07304 | I22: 4.1554 | J22: 54.93018 | K22: 0.85212 | L22: 3.85032 | M22: 6.1542
A23: T11 | B23: Test1 | C23: O0 | D23: 2.094 | E23: 1.94 | F23: 17.4 | G23: 126.84 | H23: 4.06236 | I23: 36.4356 | J23: 265.60296 | K23: 3.18288 | L23: 35.22108 | M23: 70.4631 | N23: =(D24-D23)/D23 -> -0.5 | O23: =(K24-K23)/K23 -> -0.47697368 | P23: =(L24-L23)/L23 -> -0.61355529 | Q23: =(M24-M23)/M23 -> -0.64933135
C24: O3 | D24: 1.047 | E24: 2.01 | F24: 13.58 | G24: 116.79 | H24: 2.10447 | I24: 14.21826 | J24: 122.27913 | K24: 1.66473 | L24: 13.611 | M24: 24.7092
B25: Test2 | C25: O0 | D25: 2.093 | E25: 1.94 | F25: 17.09 | G25: 125.22 | H25: 4.06042 | I25: 35.76937 | J25: 262.08546 | K25: 3.18136 | L25: 34.55543 | M25: 67.03879 | N25: =(D26-D25)/D25 -> -0.49976111 | O25: =(K26-K25)/K25 -> -0.48001484 | P25: =(L26-L25)/L25 -> -0.69367564 | Q25: =(M26-M25)/M25 -> -0.73262286
C26: O3 | D26: 1.047 | E26: 2 | F26: 10.69 | G26: 110.3 | H26: 2.094 | I26: 11.19243 | J26: 115.4841 | K26: 1.65426 | L26: 10.58517 | M26: 17.92464
A27: T12 | B27: Test1 | C27: O0 | D27: 1.047 | E27: 2 | F27: 13.98 | G27: 116.33 | H27: 2.094 | I27: 14.63706 | J27: 121.79751 | K27: 1.65426 | L27: 14.0298 | M27: 23.52609 | N27: =(D28-D27)/D27 -> -0.43266476 | O27: =(K28-K27)/K27 -> -0.40393892 | P27: =(L28-L27)/L27 -> -0.6447804 | Q27: =(M28-M27)/M27 -> -0.66242669
C28: O3 | D28: 0.594 | E28: 2.08 | F28: 8.97 | G28: 107.23 | H28: 1.23552 | I28: 5.32818 | J28: 63.69462 | K28: 0.98604 | L28: 4.98366 | M28: 7.94178
B29: Test2 | C29: O0 | D29: 1.047 | E29: 2 | F29: 10.54 | G29: 111.73 | H29: 2.094 | I29: 11.03538 | J29: 116.98131 | K29: 1.65426 | L29: 10.42812 | M29: 18.69942 | N29: =(D30-D29)/D29 -> -0.41642789 | O29: =(K30-K29)/K29 -> -0.38687993 | P29: =(L30-L29)/L29 -> -0.51193216 | Q29: =(M30-M29)/M29 -> -0.54320615
C30: O3 | D30: 0.611 | E30: 2.08 | F30: 8.91 | G30: 107.85 | H30: 1.27088 | I30: 5.44401 | J30: 65.89635 | K30: 1.01426 | L30: 5.08963 | M30: 8.54178
A31: T13 | B31: Test1 | C31: O0 | D31: 8.376 | E31: 1.92 | F31: 23.19 | G31: 141.44 | H31: 16.08192 | I31: 194.23944 | J31: 1184.7014 | K31: 12.564 | L31: 189.38136 | M31: 418.63248 | N31: =(D32-D31)/D31 -> -0.25011939 | O31: =(K32-K31)/K31 -> -0.25011939 | P31: =(L32-L31)/L31 -> -0.28295361 | Q31: =(M32-M31)/M31 -> -0.29603045
C32: O3 | D32: 6.281 | E32: 1.92 | F32: 22.2 | G32: 138.38 | H32: 12.05952 | I32: 139.4382 | J32: 869.16478 | K32: 9.4215 | L32: 135.79522 | M32: 294.70452
B33: Test2 | C33: O0 | D33: 8.422 | E33: 1.92 | F33: 22.94 | G33: 140.91 | H33: 16.17024 | I33: 193.20068 | J33: 1186.744 | K33: 12.633 | L33: 188.31592 | M33: 416.4679 | N33: =(D34-D33)/D33 -> -0.31358347 | O33: =(K34-K33)/K33 -> -0.31358347 | P33: =(L34-L33)/L33 -> -0.37375236 | Q33: =(M34-M33)/M33 -> -0.3710509
C34: O3 | D34: 5.781 | E34: 1.92 | F34: 20.98 | G34: 136.77 | H34: 11.09952 | I34: 121.28538 | J34: 790.66737 | K34: 8.6715 | L34: 117.9324 | M34: 261.93711
A35: T16 | B35: Test1 | C35: O0 | D35: 1.047 | E35: 1.96 | F35: 10.33 | G35: 110.49 | H35: 2.05212 | I35: 11.91486 | J35: 117.61998 | K35: 1.61238 | L35: 11.3076 | M35: 20.51073 | N35: =(D36-D35)/D35 -> 0 | O35: =(K36-K35)/K35 -> -0.34694055 | P35: =(L36-L35)/L35 -> -0.53153631 | Q35: =(M36-M35)/M35 -> -0.57323313
C36: O3 | D36: 1.047 | E36: 1.96 | F36: 11.38 | G36: 112.34 | H36: 1.3243 | I36: 5.67188 | J36: 68.67626 | K36: 1.05298 | L36: 5.2972 | M36: 8.7533
B37: Test2 | C37: O0 | D37: 0.68 | E37: 2.07 | F37: 8.61 | G37: 105.35 | H37: 2.05212 | I37: 10.81551 | J37: 115.68303 | K37: 1.61238 | L37: 10.20825 | M37: 18.56331 | N37: =(D38-D37)/D37 -> -0.05 | O37: =(K38-K37)/K37 -> -0.33386671 | P37: =(L38-L37)/L37 -> -0.47782235 | Q37: =(M38-M37)/M37 -> -0.51533913
C38: O3 | D38: 0.646 | E38: 2.05 | F38: 8.78 | G38: 106.31 | H38: 1.35252 | I38: 5.71506 | J38: 70.49016 | K38: 1.07406 | L38: 5.33052 | M38: 8.99691
A39: T17 | B39: Test1 | C39: O0 | D39: 1.046 | E39: 1.94 | F39: 10.4 | G39: 109.59 | H39: 2.02924 | I39: 10.8784 | J39: 114.63114 | K39: 1.58992 | L39: 10.27172 | M39: 18.54558 | N39: =(D40-D39)/D39 -> -0.33269598 | O39: =(K40-K39)/K39 -> -0.29757472 | P39: =(L40-L39)/L39 -> -0.4645259 | Q39: =(M40-M39)/M39 -> -0.42490664
C40: O3 | D40: 0.698 | E40: 2.02 | F40: 8.46 | G40: 107.14 | H40: 1.40996 | I40: 5.90508 | J40: 74.78372 | K40: 1.1168 | L40: 5.50024 | M40: 10.66544
...

Sheet C Optimization results
B1: Standard | F1: Efficient
A2: Technique | B2: Optimization level O0 (J) | C2: Optimization level O3 (J) | D2: Impact (%) | E2: Effect size | F2: Optimization level O0 (J) | G2: Optimization level O3 (J) | H2: Impact (%) | I2: Effect size | J2: Average impact (%)
A3: T4 | B3: {=INDIRECT("'C Impact of Optimization'!M" & 3 + (ROW(A1)-1)*4)} -> 221.55833 | C3: {=INDIRECT("'C Impact of Optimization'!M" & 4 + (ROW(A1)-1)*4)} -> 118.6606 | D3: {=INDIRECT("'C Impact of Optimization'!Q" & 3 + (ROW(A1)-1)*4)*100} -> -46.442727 | E3: large | F3: {=INDIRECT("'C Impact of Optimization'!M" & 5 + (ROW(A1)-1)*4)} -> 142.38304 | G3: {=INDIRECT("'C Impact of Optimization'!M" & 6 + (ROW(A1)-1)*4)} -> 21.31568 | H3: {=INDIRECT("'C Impact of Optimization'!Q" & 5 + (ROW(D1)-1)*4)*100} -> -85.029341 | I3: large | J3: =AVERAGE(D3,H3) -> -65.736034 | N3: Standard | R3: Efficient
A4: T7 | B4: {=INDIRECT("'C Impact of Optimization'!M" & 3 + (ROW(A2)-1)*4)} -> 63.53196 | C4: {=INDIRECT("'C Impact of Optimization'!M" & 4 + (ROW(A2)-1)*4)} -> 63.10395 | D4: {=INDIRECT("'C Impact of Optimization'!Q" & 3 + (ROW(A2)-1)*4)*100} -> -0.67369242 | E4: large | F4: {=INDIRECT("'C Impact of Optimization'!M" & 5 + (ROW(A2)-1)*4)} -> 27.3006 | G4: {=INDIRECT("'C Impact of Optimization'!M" & 6 + (ROW(A2)-1)*4)} -> 28.41558 | H4: {=INDIRECT("'C Impact of Optimization'!Q" & 5 + (ROW(D2)-1)*4)*100} -> 4.0840861 | I4: large | J4: =AVERAGE(D4,H4) -> 1.7051968 | N4: Impact | O4: Techniques | R4: Impact | S4: Techniques
A5: T8 | B5: {=INDIRECT("'C Impact of Optimization'!M" & 3 + (ROW(A3)-1)*4)} -> 243.32315 | C5: {=INDIRECT("'C Impact of Optimization'!M" & 4 + (ROW(A3)-1)*4)} -> 1126.5793 | D5: {=INDIRECT("'C Impact of Optimization'!Q" & 3 + (ROW(A3)-1)*4)*100} -> 362.99718 | E5: small~ | F5: {=INDIRECT("'C Impact of Optimization'!M" & 5 + (ROW(A3)-1)*4)} -> 288.47541 | G5: {=INDIRECT("'C Impact of Optimization'!M" & 6 + (ROW(A3)-1)*4)} -> 226.6719 | H5: {=INDIRECT("'C Impact of Optimization'!Q" & 5 + (ROW(D3)-1)*4)*100} -> -21.424187 | I5: medium | J5: =AVERAGE(D5,H5) -> 170.7865 | N5: <= -75 | O5: {=_xlfn.TEXTJOIN(", ", TRUE, IF(D3:D25 <= -75, A3:A25, ""))} -> T19, T20, T25, T28, T36, T49 | R5: <= -75 | S5: {=_xlfn.TEXTJOIN(", ", TRUE, IF(H3:H25 <= -75, A3:A25, ""))} -> T4, T19, T25, T26, T28, T36, T40, T49
A6: T9 | B6: {=INDIRECT("'C Impact of Optimization'!M" & 3 + (ROW(A4)-1)*4)} -> 7.336 | C6: {=INDIRECT("'C Impact of Optimization'!M" & 4 + (ROW(A4)-1)*4)} -> 6.30372 | D6: {=INDIRECT("'C Impact of Optimization'!Q" & 3 + (ROW(A4)-1)*4)*100} -> -14.071429 | E6: large | F6: {=INDIRECT("'C Impact of Optimization'!M" & 5 + (ROW(A4)-1)*4)} -> 6.4976 | G6: {=INDIRECT("'C Impact of Optimization'!M" & 6 + (ROW(A4)-1)*4)} -> 6.10864 | H6: {=INDIRECT("'C Impact of Optimization'!Q" & 5 + (ROW(D4)-1)*4)*100} -> -5.9862103 | I6: large | J6: =AVERAGE(D6,H6) -> -10.028819 | N6: > -75 & <= -25 | O6: {=_xlfn.TEXTJOIN(", ", TRUE, IF((D3:D25 > -75) * (D3:D25 <= -25), A3:A25, ""))} -> T4, T11, T12, T13, T16, T17, T26, T29, T32, T40 | R6: > -75 & <= -25 | S6: {=_xlfn.TEXTJOIN(", ", TRUE, IF((H3:H25 > -75) * (H3:H25 <= -25), A3:A25, ""))} -> T10, T11, T12, T13, T16, T17, T20, T29, T32
A7: T10 | B7: {=INDIRECT("'C Impact of Optimization'!M" & 3 + (ROW(A5)-1)*4)} -> 4730.4698 | C7: {=INDIRECT("'C Impact of Optimization'!M" & 4 + (ROW(A5)-1)*4)} -> 4750.516 | D7: {=INDIRECT("'C Impact of Optimization'!Q" & 3 + (ROW(A5)-1)*4)*100} -> 0.42376763 | E7: medium | F7: {=INDIRECT("'C Impact of Optimization'!M" & 5 + (ROW(A5)-1)*4)} -> 14.45125 | G7: {=INDIRECT("'C Impact of Optimization'!M" & 6 + (ROW(A5)-1)*4)} -> 6.1542 | H7: {=INDIRECT("'C Impact of Optimization'!Q" & 5 + (ROW(D5)-1)*4)*100} -> -57.414065 | I7: small~ | J7: =AVERAGE(D7,H7) -> -28.495148 | N7: > -25 & <= -3 | O7: {=_xlfn.TEXTJOIN(", ", TRUE, IF((D3:D25 > -25) * (D3:D25 <= -3), A3:A25, ""))} -> T9, T31, T33, T44 | R7: > -25 & <= -3 | S7: {=_xlfn.TEXTJOIN(", ", TRUE, IF((H3:H25 > -25) * (H3:H25 <= -3), A3:A25, ""))} -> T8, T9, T31, T33
A8: T11 | B8: {=INDIRECT("'C Impact of Optimization'!M" & 3 + (ROW(A6)-1)*4)} -> 70.4631 | C8: {=INDIRECT("'C Impact of Optimization'!M" & 4 + (ROW(A6)-1)*4)} -> 24.7092 | D8: {=INDIRECT("'C Impact of Optimization'!Q" & 3 + (ROW(A6)-1)*4)*100} -> -64.933135 | E8: small~ | F8: {=INDIRECT("'C Impact of Optimization'!M" & 5 + (ROW(A6)-1)*4)} -> 67.03879 | G8: {=INDIRECT("'C Impact of Optimization'!M" & 6 + (ROW(A6)-1)*4)} -> 17.92464 | H8: {=INDIRECT("'C Impact of Optimization'!Q" & 5 + (ROW(D6)-1)*4)*100} -> -73.262286 | I8: large | J8: =AVERAGE(D8,H8) -> -69.097711 | N8: > -3 & < 3 | O8: {=_xlfn.TEXTJOIN(", ", TRUE, IF((D3:D25 > -3) * (D3:D25 < 3), A3:A25, ""))} -> T7, T10 | R8: > -3 & < 3 | S8: {=_xlfn.TEXTJOIN(", ", TRUE, IF((H3:H25 > -3) * (H3:H25 < 3), A3:A25, ""))}
A9: T12 | B9: {=INDIRECT("'C Impact of Optimization'!M" & 3 + (ROW(A7)-1)*4)} -> 23.52609 | C9: {=INDIRECT("'C Impact of Optimization'!M" & 4 + (ROW(A7)-1)*4)} -> 7.94178 | D9: {=INDIRECT("'C Impact of Optimization'!Q" & 3 + (ROW(A7)-1)*4)*100} -> -66.242669 | E9: large | F9: {=INDIRECT("'C Impact of Optimization'!M" & 5 + (ROW(A7)-1)*4)} -> 18.69942 | G9: {=INDIRECT("'C Impact of Optimization'!M" & 6 + (ROW(A7)-1)*4)} -> 8.54178 | H9: {=INDIRECT("'C Impact of Optimization'!Q" & 5 + (ROW(D7)-1)*4)*100} -> -54.320615 | I9: large | J9: =AVERAGE(D9,H9) -> -60.281642 | N9: >= 3 & < 25 | O9: {=_xlfn.TEXTJOIN(", ", TRUE, IF((D3:D25 >= 3) * (D3:D25 < 25), A3:A25, ""))} | R9: >= 3 & < 25 | S9: {=_xlfn.TEXTJOIN(", ", TRUE, IF((H3:H25 >= 3) * (H3:H25 < 25), A3:A25, ""))} -> T7, T44
A10: T13 | B10: {=INDIRECT("'C Impact of Optimization'!M" & 3 + (ROW(A8)-1)*4)} -> 418.63248 | C10: {=INDIRECT("'C Impact of Optimization'!M" & 4 + (ROW(A8)-1)*4)} -> 294.70452 | D10: {=INDIRECT("'C Impact of Optimization'!Q" & 3 + (ROW(A8)-1)*4)*100} -> -29.603045 | E10: large | F10: {=INDIRECT("'C Impact of Optimization'!M" & 5 + (ROW(A8)-1)*4)} -> 416.4679 | G10: {=INDIRECT("'C Impact of Optimization'!M" & 6 + (ROW(A8)-1)*4)} -> 261.93711 | H10: {=INDIRECT("'C Impact of Optimization'!Q" & 5 + (ROW(D8)-1)*4)*100} -> -37.10509 | I10: large | J10: =AVERAGE(D10,H10) -> -33.354067 | N10: >= 25 & < 75 | O10: {=_xlfn.TEXTJOIN(", ", TRUE, IF((D3:D25 >= 25) * (D3:D25 < 75), A3:A25, ""))} | R10: >= 25 & < 75 | S10: {=_xlfn.TEXTJOIN(", ", TRUE, IF((H3:H25 >= 25) * (H3:H25 < 75), A3:A25, ""))}
A11: T16 | B11: {=INDIRECT("'C Impact of Optimization'!M" & 3 + (ROW(A9)-1)*4)} -> 20.51073 | C11: {=INDIRECT("'C Impact of Optimization'!M" & 4 + (ROW(A9)-1)*4)} -> 8.7533 | D11: {=INDIRECT("'C Impact of Optimization'!Q" & 3 + (ROW(A9)-1)*4)*100} -> -57.323313 | E11: large | F11: {=INDIRECT("'C Impact of Optimization'!M" & 5 + (ROW(A9)-1)*4)} -> 18.56331 | G11: {=INDIRECT("'C Impact of Optimization'!M" & 6 + (ROW(A9)-1)*4)} -> 8.99691 | H11: {=INDIRECT("'C Impact of Optimization'!Q" & 5 + (ROW(D9)-1)*4)*100} -> -51.533913 | I11: large | J11: =AVERAGE(D11,H11) -> -54.428613 | N11: >= 75 | O11: {=_xlfn.TEXTJOIN(", ", TRUE, IF(D3:D25 >= 75, A3:A25, ""))} -> T8 | R11: >= 75 | S11: {=_xlfn.TEXTJOIN(", ", TRUE, IF(H3:H25 >= 75, A3:A25, ""))}
A12: T17 | B12: {=INDIRECT("'C Impact of Optimization'!M" & 3 + (ROW(A10)-1)*4)} -> 18.54558 | C12: {=INDIRECT("'C Impact of Optimization'!M" & 4 + (ROW(A10)-1)*4)} -> 10.66544 | D12: {=INDIRECT("'C Impact of Optimization'!Q" & 3 + (ROW(A10)-1)*4)*100} -> -42.490664 | E12: large | F12: {=INDIRECT("'C Impact of Optimization'!M" & 5 + (ROW(A10)-1)*4)} -> 19.5789 | G12: {=INDIRECT("'C Impact of Optimization'!M" & 6 + (ROW(A10)-1)*4)} -> 9.18 | H12: {=INDIRECT("'C Impact of Optimization'!Q" & 5 + (ROW(D10)-1)*4)*100} -> -53.11279 | I12: large | J12: =AVERAGE(D12,H12) -> -47.801727
A13: T19 | B13: {=INDIRECT("'C Impact of Optimization'!M" & 3 + (ROW(A11)-1)*4)} -> 673.59663 | C13: {=INDIRECT("'C Impact of Optimization'!M" & 4 + (ROW(A11)-1)*4)} -> 46.1423 | D13: {=INDIRECT("'C Impact of Optimization'!Q" & 3 + (ROW(A11)-1)*4)*100} -> -93.149862 | E13: large | F13: {=INDIRECT("'C Impact of Optimization'!M" & 5 + (ROW(A11)-1)*4)} -> 887.26553 | G13: {=INDIRECT("'C Impact of Optimization'!M" & 6 + (ROW(A11)-1)*4)} -> 50.24322 | H13: {=INDIRECT("'C Impact of Optimization'!Q" & 5 + (ROW(D11)-1)*4)*100} -> -94.337296 | I13: large | J13: =AVERAGE(D13,H13) -> -93.743579
A14: T20 | B14: {=INDIRECT("'C Impact of Optimization'!M" & 3 + (ROW(A12)-1)*4)} -> 436.98078 | C14: {=INDIRECT("'C Impact of Optimization'!M" & 4 + (ROW(A12)-1)*4)} -> 26.86602 | D14: {=INDIRECT("'C Impact of Optimization'!Q" & 3 + (ROW(A12)-1)*4)*100} -> -93.851899 | E14: large | F14: {=INDIRECT("'C Impact of Optimization'!M" & 5 + (ROW(A12)-1)*4)} -> 145.371 | G14: {=INDIRECT("'C Impact of Optimization'!M" & 6 + (ROW(A12)-1)*4)} -> 44.18754 | H14: {=INDIRECT("'C Impact of Optimization'!Q" & 5 + (ROW(D12)-1)*4)*100} -> -69.603607 | I14: large | J14: =AVERAGE(D14,H14) -> -81.727753
A15: T25 | B15: {=INDIRECT("'C Impact of Optimization'!M" & 3 + (ROW(A13)-1)*4)} -> 900.2326 | C15: {=INDIRECT("'C Impact of Optimization'!M" & 4 + (ROW(A13)-1)*4)} -> 192.984 | D15: {=INDIRECT("'C Impact of Optimization'!Q" & 3 + (ROW(A13)-1)*4)*100} -> -78.562874 | E15: large | F15: {=INDIRECT("'C Impact of Optimization'!M" & 5 + (ROW(A13)-1)*4)} -> 729.2229 | G15: {=INDIRECT("'C Impact of Optimization'!M" & 6 + (ROW(A13)-1)*4)} -> 145.28371 | H15: {=INDIRECT("'C Impact of Optimization'!Q" & 5 + (ROW(D13)-1)*4)*100} -> -80.076913 | I15: large | J15: =AVERAGE(D15,H15) -> -79.319894
A16: T26 | B16: {=INDIRECT("'C Impact of Optimization'!M" & 3 + (ROW(A14)-1)*4)} -> 946.51452 | C16: {=INDIRECT("'C Impact of Optimization'!M" & 4 + (ROW(A14)-1)*4)} -> 238.577 | D16: {=INDIRECT("'C Impact of Optimization'!Q" & 3 + (ROW(A14)-1)*4)*100} -> -74.794153 | E16: large | F16: {=INDIRECT("'C Impact of Optimization'!M" & 5 + (ROW(A14)-1)*4)} -> 944.87532 | G16: {=INDIRECT("'C Impact of Optimization'!M" & 6 + (ROW(A14)-1)*4)} -> 26.21604 | H16: {=INDIRECT("'C Impact of Optimization'!Q" & 5 + (ROW(D14)-1)*4)*100} -> -97.22545 | I16: large | J16: =AVERAGE(D16,H16) -> -86.009801
A17: T28 | B17: {=INDIRECT("'C Impact of Optimization'!M" & 3 + (ROW(A15)-1)*4)} -> 344.20188 | C17: {=INDIRECT("'C Impact of Optimization'!M" & 4 + (ROW(A15)-1)*4)} -> 35.9373 | D17: {=INDIRECT("'C Impact of Optimization'!Q" & 3 + (ROW(A15)-1)*4)*100} -> -89.559238 | E17: large | F17: {=INDIRECT("'C Impact of Optimization'!M" & 5 + (ROW(A15)-1)*4)} -> 693.75799 | G17: {=INDIRECT("'C Impact of Optimization'!M" & 6 + (ROW(A15)-1)*4)} -> 33.65609 | H17: {=INDIRECT("'C Impact of Optimization'!Q" & 5 + (ROW(D15)-1)*4)*100} -> -95.148728 | I17: large | J17: =AVERAGE(D17,H17) -> -92.353983
A18: T29 | B18: {=INDIRECT("'C Impact of Optimization'!M" & 3 + (ROW(A16)-1)*4)} -> 14.3439 | C18: {=INDIRECT("'C Impact of Optimization'!M" & 4 + (ROW(A16)-1)*4)} -> 6.4452 | D18: {=INDIRECT("'C Impact of Optimization'!Q" & 3 + (ROW(A16)-1)*4)*100} -> -55.066614 | E18: large | F18: {=INDIRECT("'C Impact of Optimization'!M" & 5 + (ROW(A16)-1)*4)} -> 13.90416 | G18: {=INDIRECT("'C Impact of Optimization'!M" & 6 + (ROW(A16)-1)*4)} -> 6.75716 | H18: {=INDIRECT("'C Impact of Optimization'!Q" & 5 + (ROW(D16)-1)*4)*100} -> -51.401883 | I18: large | J18: =AVERAGE(D18,H18) -> -53.234248
A19: T31 | B19: {=INDIRECT("'C Impact of Optimization'!M" & 3 + (ROW(A17)-1)*4)} -> 978.7239 | C19: {=INDIRECT("'C Impact of Optimization'!M" & 4 + (ROW(A17)-1)*4)} -> 756.50404 | D19: {=INDIRECT("'C Impact of Optimization'!Q" & 3 + (ROW(A17)-1)*4)*100} -> -22.705061 | E19: large | F19: {=INDIRECT("'C Impact of Optimization'!M" & 5 + (ROW(A17)-1)*4)} -> 2084.8756 | G19: {=INDIRECT("'C Impact of Optimization'!M" & 6 + (ROW(A17)-1)*4)} -> 1718.9779 | H19: {=INDIRECT("'C Impact of Optimization'!Q" & 5 + (ROW(D17)-1)*4)*100} -> -17.550098 | I19: large | J19: =AVERAGE(D19,H19) -> -20.12758
A20: T32 | B20: {=INDIRECT("'C Impact of Optimization'!M" & 3 + (ROW(A18)-1)*4)} -> 18.96117 | C20: {=INDIRECT("'C Impact of Optimization'!M" & 4 + (ROW(A18)-1)*4)} -> 7.14212 | D20: {=INDIRECT("'C Impact of Optimization'!Q" & 3 + (ROW(A18)-1)*4)*100} -> -62.332915 | E20: large | F20: {=INDIRECT("'C Impact of Optimization'!M" & 5 + (ROW(A18)-1)*4)} -> 15.87252 | G20: {=INDIRECT("'C Impact of Optimization'!M" & 6 + (ROW(A18)-1)*4)} -> 7.61896 | H20: {=INDIRECT("'C Impact of Optimization'!Q" & 5 + (ROW(D18)-1)*4)*100} -> -51.999052 | I20: large | J20: =AVERAGE(D20,H20) -> -57.165984
A21: T33 | B21: {=INDIRECT("'C Impact of Optimization'!M" & 3 + (ROW(A19)-1)*4)} -> 24.97616 | C21: {=INDIRECT("'C Impact of Optimization'!M" & 4 + (ROW(A19)-1)*4)} -> 20.33274 | D21: {=INDIRECT("'C Impact of Optimization'!Q" & 3 + (ROW(A19)-1)*4)*100} -> -18.591409 | E21: large | F21: {=INDIRECT("'C Impact of Optimization'!M" & 5 + (ROW(A19)-1)*4)} -> 25.90278 | G21: {=INDIRECT("'C Impact of Optimization'!M" & 6 + (ROW(A19)-1)*4)} -> 21.54726 | H21: {=INDIRECT("'C Impact of Optimization'!Q" & 5 + (ROW(D19)-1)*4)*100} -> -16.814875 | I21: large | J21: =AVERAGE(D21,H21) -> -17.703142
A22: T36 | B22: {=INDIRECT("'C Impact of Optimization'!M" & 3 + (ROW(A20)-1)*4)} -> 178.74303 | C22: {=INDIRECT("'C Impact of Optimization'!M" & 4 + (ROW(A20)-1)*4)} -> 5.29799 | D22: {=INDIRECT("'C Impact of Optimization'!Q" & 3 + (ROW(A20)-1)*4)*100} -> -97.035974 | E22: large | F22: {=INDIRECT("'C Impact of Optimization'!M" & 5 + (ROW(A20)-1)*4)} -> 171.01735 | G22: {=INDIRECT("'C Impact of Optimization'!M" & 6 + (ROW(A20)-1)*4)} -> 5.83145 | H22: {=INDIRECT("'C Impact of Optimization'!Q" & 5 + (ROW(D20)-1)*4)*100} -> -96.590141 | I22: large | J22: =AVERAGE(D22,H22) -> -96.813058
A23: T40 | B23: {=INDIRECT("'C Impact of Optimization'!M" & 3 + (ROW(A21)-1)*4)} -> 625.08848 | C23: {=INDIRECT("'C Impact of Optimization'!M" & 4 + (ROW(A21)-1)*4)} -> 263.63058 | D23: {=INDIRECT("'C Impact of Optimization'!Q" & 3 + (ROW(A21)-1)*4)*100} -> -57.825078 | E23: large | F23: {=INDIRECT("'C Impact of Optimization'!M" & 5 + (ROW(A21)-1)*4)} -> 542.62944 | G23: {=INDIRECT("'C Impact of Optimization'!M" & 6 + (ROW(A21)-1)*4)} -> 52.13562 | H23: {=INDIRECT("'C Impact of Optimization'!Q" & 5 + (ROW(D21)-1)*4)*100} -> -90.39204 | I23: large | J23: =AVERAGE(D23,H23) -> -74.108559
... A25: T49 | B25: {=INDIRECT("'C Impact of Optimization'!M" & 3 + (ROW(A23)-1)*4)} -> 417.29232 | C25: {=INDIRECT("'C Impact of Optimization'!M" & 4 + (ROW(A23)-1)*4)} -> 7.25401 | D25: {=INDIRECT("'C Impact of Optimization'!Q" & 3 + (ROW(A23)-1)*4)*100} -> -98.261648 | E25: small~ | F25: {=INDIRECT("'C Impact of Optimization'!M" & 5 + (ROW(A23)-1)*4)} -> 175.72839 | G25: {=INDIRECT("'C Impact of Optimization'!M" & 6 + (ROW(A23)-1)*4)} -> 40.78688 | H25: {=INDIRECT("'C Impact of Optimization'!Q" & 5 + (ROW(D23)-1)*4)*100} -> -76.789818 | I25: medium | J25: =AVERAGE(D25,H25) -> -87.525733
D32: Standard | I32: Efficient
D33: Impact | E33: Average | F33: Min | G33: Max | I33: Impact | J33: Average | K33: Min | L33: Max
D34: Reduction | E34: {=AVERAGE(_xlfn._xlws.FILTER($D$3:$D$25, ISNUMBER(MATCH($A$3:$A$25, _xlfn.TEXTSPLIT(_xlfn.TEXTJOIN(", ", TRUE, O5:O7), ", "), 0))))} -> -58.631876 | F34: {=MIN(_xlfn._xlws.FILTER($D$3:$D$25, ISNUMBER(MATCH($A$3:$A$25, _xlfn.TEXTSPLIT(_xlfn.TEXTJOIN(", ", TRUE, O5:O7), ", "), 0))))} -> -98.261648 | G34: {=MAX(_xlfn._xlws.FILTER($D$3:$D$25, ISNUMBER(MATCH($A$3:$A$25, _xlfn.TEXTSPLIT(_xlfn.TEXTJOIN(", ", TRUE, O5:O7), ", "), 0))))} -> -9.7938144 | I34: Reduction | J34: {=AVERAGE(_xlfn._xlws.FILTER($H$3:$H$25, ISNUMBER(MATCH($A$3:$A$25, _xlfn.TEXTSPLIT(_xlfn.TEXTJOIN(", ", TRUE, S5:S7), ", "), 0))))} -> -60.815162 | K34: {=MIN(_xlfn._xlws.FILTER($H$3:$H$25, ISNUMBER(MATCH($A$3:$A$25, _xlfn.TEXTSPLIT(_xlfn.TEXTJOIN(", ", TRUE, S5:S7), ", "), 0))))} -> -97.22545 | L34: {=MAX(_xlfn._xlws.FILTER($H$3:$H$25, ISNUMBER(MATCH($A$3:$A$25, _xlfn.TEXTSPLIT(_xlfn.TEXTJOIN(", ", TRUE, S5:S7), ", "), 0))))} -> -5.9862103
D35: No impact | E35: {=AVERAGE(_xlfn._xlws.FILTER($D$3:$D$25, ISNUMBER(MATCH($A$3:$A$25, _xlfn.TEXTSPLIT(_xlfn.TEXTJOIN(", ", TRUE, O8), ", "), 0))))} -> -0.12496239 | F35: {=MIN(_xlfn._xlws.FILTER($D$3:$D$25, ISNUMBER(MATCH($A$3:$A$25, _xlfn.TEXTSPLIT(_xlfn.TEXTJOIN(", ", TRUE, O8), ", "), 0))))} -> -0.67369242 | G35: {=MAX(_xlfn._xlws.FILTER($D$3:$D$25, ISNUMBER(MATCH($A$3:$A$25, _xlfn.TEXTSPLIT(_xlfn.TEXTJOIN(", ", TRUE, O8), ", "), 0))))} -> 0.42376763 | I35: No impact
D36: Increase | E36: {=AVERAGE(_xlfn._xlws.FILTER($D$3:$D$25, ISNUMBER(MATCH($A$3:$A$25, _xlfn.TEXTSPLIT(_xlfn.TEXTJOIN(", ", TRUE, O9:O11), ", "), 0))))} -> 362.99718 | F36: {=MIN(_xlfn._xlws.FILTER($D$3:$D$25, ISNUMBER(MATCH($A$3:$A$25, _xlfn.TEXTSPLIT(_xlfn.TEXTJOIN(", ", TRUE, O9:O11), ", "), 0))))} -> 362.99718 | G36: {=MAX(_xlfn._xlws.FILTER($D$3:$D$25, ISNUMBER(MATCH($A$3:$A$25, _xlfn.TEXTSPLIT(_xlfn.TEXTJOIN(", ", TRUE, O9:O11), ", "), 0))))} -> 362.99718 | I36: Increase | J36: {=AVERAGE(_xlfn._xlws.FILTER($H$3:$H$25, ISNUMBER(MATCH($A$3:$A$25, _xlfn.TEXTSPLIT(_xlfn.TEXTJOIN(", ", TRUE, S9:S11), ", "), 0))))} -> 11.908512 | K36: {=MIN(_xlfn._xlws.FILTER($H$3:$H$25, ISNUMBER(MATCH($A$3:$A$25, _xlfn.TEXTSPLIT(_xlfn.TEXTJOIN(", ", TRUE, S9:S11), ", "), 0))))} -> 4.0840861 | L36: {=MAX(_xlfn._xlws.FILTER($H$3:$H$25, ISNUMBER(MATCH($A$3:$A$25, _xlfn.TEXTSPLIT(_xlfn.TEXTJOIN(", ", TRUE, S9:S11), ", "), 0))))} -> 19.732938

Sheet Python Impact of Technique
A1: Tecnica | B1: Code REPS | C1: Extrapolate | D1: Optimization | E1: Test | F1: Time (s) | G1: Power | J1: Consumption (with baseline) | M1: Consumption (without baseline) | P1: Consumption (without baseline) Extrapolate | S1: Impact of Technique ((Test2-Test1)/Test1%)
G2: HDD (w) | H2: CPU (w) | I2: DUT (w) | J2: HDD (J) | K2: CPU (J) | L2: DUT (J) | M2: HDD (J) | N2: CPU (J) | O2: DUT (J) | P2: HDD (J) | Q2: CPU (J) | R2: DUT (J) | S2: Time (s) | T2: HDD (J) | U2: CPU (J) | V2: DUT (J)
A3: T4 | B3: 100000000 | C3: =100000000/B3 -> 1 | D3: Interpreter | E3: Test1 | F3: 88.541 | G3: 1.63 | H3: 26.21 | I3: 175.9 | J3: 144.32183 | K3: 2320.6596 | L3: 15574.362 | M3: 107.13461 | N3: 2269.3058 | O3: 5830.4248 | P3: =M3*C3 -> 107.13461 | Q3: =N3*C3 -> 2269.3058 | R3: =O3*C3 -> 5830.4248 | S3: =(F4-F3)/F3 -> -0.47006472 | T3: =(P4-P3)/P3 -> -0.045240562 | U3: =(Q4-Q3)/Q3 -> -0.48288406 | V3: =(R4-R3)/R3 -> -0.50241612
B4: 100000000 | C4: 1 | E4: Test2 | F4: 46.921 | G4: 2.6 | H4: 25.59 | I4: 171.89 | J4: 121.9946 | K4: 1200.7084 | L4: 8065.2507 | M4: 102.28778 | N4: 1173.4942 | O4: 2901.1254 | P4: =M4*C4 -> 102.28778 | Q4: =N4*C4 -> 1173.4942 | R4: =O4*C4 -> 2901.1254
B5: 100000000 | C5: 1 | D5: Nuitka | E5: Test1 | F5: 130.288 | G5: 2.06 | H5: 25.23 | I5: 172.23 | J5: 268.39328 | K5: 3287.1662 | L5: 22439.502 | M5: 213.67232 | N5: 3211.5992 | O5: 8100.005 | P5: =M5*C5 -> 213.67232 | Q5: =N5*C5 -> 3211.5992 | R5: =O5*C5 -> 8100.005 | S5: =(F6-F5)/F5 -> -0.66337652 | T5: =(P6-P5)/P5 -> -0.54843192 | U5: =(Q6-Q5)/Q5 -> -0.67416486 | V5: =(R6-R5)/R5 -> -0.67469296
B6: 100000000 | C6: 1 | E6: Test2 | F6: 43.858 | G6: 2.62 | H6: 24.44 | I6: 170.14 | J6: 114.90796 | K6: 1071.8895 | L6: 7462.0001 | M6: 96.4876 | N6: 1046.4519 | O6: 2634.9886 | P6: =M6*C6 -> 96.4876 | Q6: =N6*C6 -> 1046.4519 | R6: =O6*C6 -> 2634.9886
A7: T7 | B7: 100000000 | C7: 1 | D7: Interpreter | E7: Test1 | F7: 20.123 | G7: 5.76 | H7: 36.47 | I7: 165.68 | J7: 115.90848 | K7: 733.88581 | L7: 3333.9786 | M7: 107.45682 | N7: 698.87179 | O7: 1405.7928 | P7: =M7*C7 -> 107.45682 | Q7: =N7*C7 -> 698.87179 | R7: =O7*C7 -> 1405.7928 | S7: =(F8-F7)/F7 -> -0.29568156 | T7: =(P8-P7)/P7 -> -0.57925546 | U7: =(Q8-Q7)/Q7 -> -0.38389881 | V7: =(R8-R7)/R7 -> -0.32058374
B8: 100000000 | C8: 1 | E8: Test2 | F8: 14.173 | G8: 3.61 | H8: 32.12 | I8: 163.21 | J8: 51.16453 | K8: 455.23676 | L8: 2313.1753 | M8: 45.21187 | N8: 430.57574 | O8: 955.11847 | P8: =M8*C8 -> 45.21187 | Q8: =N8*C8 -> 430.57574 | R8: =O8*C8 -> 955.11847
B9: 100000000 | C9: 1 | D9: Nuitka | E9: Test1 | F9: 19.2 | G9: 3.87 | H9: 31.22 | I9: 161.52 | J9: 74.304 | K9: 599.424 | L9: 3101.184 | M9: 66.24 | N9: 566.016 | O9: 1261.44 | P9: =M9*C9 -> 66.24 | Q9: =N9*C9 -> 566.016 | R9: =O9*C9 -> 1261.44 | S9: =(F10-F9)/F9 -> -0.40328125 | T9: =(P10-P9)/P9 -> -0.44652174 | U9: =(Q10-Q9)/Q9 -> -0.42696378 | V9: =(R10-R9)/R9 -> -0.42716816
B10: 100000000 | C10: 1 | E10: Test2 | F10: 11.457 | G10: 3.62 | H10: 30.05 | I10: 158.89 | J10: 41.47434 | K10: 344.28285 | L10: 1820.4027 | M10: 36.6624 | N10: 324.34767 | O10: 722.59299 | P10: =M10*C10 -> 36.6624 | Q10: =N10*C10 -> 324.34767 | R10: =O10*C10 -> 722.59299
A11: T8 | B11: 100000000 | C11: 1 | D11: Interpreter | E11: Test1 | F11: 24.572 | G11: 5.87 | H11: 32.43 | I11: 156.43 | J11: 144.23764 | K11: 796.86996 | L11: 3843.798 | M11: 102.95668 | N11: 711.11368 | O11: 1393.7238 | P11: =M11*C11 -> 102.95668 | Q11: =N11*C11 -> 711.11368 | R11: =O11*C11 -> 1393.7238 | S11: =(F12-F11)/F11 -> -0.71129741 | T11: =(P12-P11)/P11 -> -0.71405352 | U11: =(Q12-Q11)/Q11 -> -0.71578657 | V11: =(R12-R11)/R11 -> -0.70722544
B12: 100000000 | C12: 1 | E12: Test2 | F12: 7.094 | G12: 5.83 | H12: 31.98 | I12: 157.23 | J12: 41.35802 | K12: 226.86612 | L12: 1115.3896 | M12: 29.4401 | N12: 202.10806 | O12: 408.04688 | P12: =M12*C12 -> 29.4401 | Q12: =N12*C12 -> 202.10806 | R12: =O12*C12 -> 408.04688
B13: 100000000 | C13: 1 | D13: Nuitka | E13: Test1 | F13: 18.325 | G13: 5.85 | H13: 31.82 | I13: 155.79 | J13: 107.20125 | K13: 583.1015 | L13: 2854.8517 | M13: 76.41525 | N13: 519.14725 | O13: 1027.666 | P13: =M13*C13 -> 76.41525 | Q13: =N13*C13 -> 519.14725 | R13: =O13*C13 -> 1027.666 | S13: =(F14-F13)/F13 -> -0.57746248 | T13: =(P14-P13)/P13 -> -0.58252888 | U13: =(Q14-Q13)/Q13 -> -0.55688 | V13: =(R14-R13)/R13 -> -0.5354197
